Workbook
Name Age_3_pollock: 'pollock Model 2017 data'!$O$2:$Y$56
Name Ianelli_Table_1.30_et_al_2016_pollock_Model_2016: 'pollock Model 2017 data'!$A$1:$M$57

Sheet All data
B1: Sea surface temperature. | N1: TCindex | O1: Pollock (by age)
B2: Jan | C2: Feb | D2: Mar | E2: April | F2: May | G2: June | H2: July | I2: Aug | J2: Sept | K2: Oct | L2: Nov | M2: Dec | O2: 1 | P2: 2 | Q2: 3 | R2: 4 | S2: 5 | T2: 6 | U2: 7 | V2: 8 | W2: 9 | X2: 10+ | Y2: Total
A3: 1948 | B3: 2.304 | C3: 2.197 | D3: 1.256 | E3: 0.547 | F3: 0.434 | G3: 4.079 | H3: 7.476 | I3: 8.667 | J3: 9.166 | K3: 6.206 | L3: 4.348 | M3: 3.491
A4: 1949 | B4: 2.338 | C4: 1.766 | D4: 1.082 | E4: 0.613 | F4: 0.373 | G4: 3.755 | H4: 7.349 | I4: 9.279 | J4: 8.75 | K4: 6.847 | L4: 5.045 | M4: 3.843 | N4: =G4-I3 -> -4.912
A5: 1950 | B5: 2.544 | C5: -0.857 | D5: 0.014 | E5: -1.024 | F5: -0.475 | G5: 3.336 | H5: 6.997 | I5: 8.992 | J5: 8.734 | K5: 6.484 | L5: 4.432 | M5: 3.152 | N5: =G5-I4 -> -5.943
A6: 1951 | B6: 2.349 | C6: 0.403 | D6: -1.335 | E6: -1.134 | F6: 0.563 | G6: 3.878 | H6: 8.179 | I6: 9.891 | J6: 9.61 | K6: 7.735 | L6: 5.495 | M6: 3.946 | N6: =G6-I5 -> -5.114
A7: 1952 | B7: 2.5 | C7: -0.435 | D7: -0.736 | E7: -2.783 | F7: 0.116 | G7: 3.56 | H7: 7.325 | I7: 9.296 | J7: 8.995 | K7: 7.558 | L7: 5.175 | M7: 3.635 | N7: =G7-I6 -> -6.331
A8: 1953 | B8: 2.591 | C8: 0.64 | D8: -5.238 | E8: 0.998 | F8: 3.014 | G8: 5.773 | H8: 8.702 | I8: 10.042 | J8: 9.347 | K8: 7.221 | L8: 5.312 | M8: 3.763 | N8: =G8-I7 -> -3.523
A9: 1954 | B9: 2.211 | C9: -8.6 | D9: -2.597 | E9: 1.442 | F9: 2.553 | G9: 5.5 | H9: 8.168 | I9: 9.849 | J9: 9.209 | K9: 7.285 | L9: 5.222 | M9: 3.778 | N9: =G9-I8 -> -4.542
A10: 1955 | B10: 2.811 | C10: 0.207 | D10: 0.219 | E10: 1.456 | F10: 2.268 | G10: 4.435 | H10: 7.316 | I10: 9.186 | J10: 8.729 | K10: 6.55 | L10: 4.45 | M10: 2.846 | N10: =G10-I9 -> -5.414
A11: 1956 | B11: -4.95 | C11: -7.941 | D11: -8.757 | E11: -2.193 | F11: 1.687 | G11: 4.53 | H11: 7.876 | I11: 9.515 | J11: 8.703 | K11: 6.5 | L11: 3.575 | M11: 0.567 | N11: =G11-I10 -> -4.656
A12: 1957 | B12: 1.35 | C12: 0.588 | D12: -2.605 | E12: 1.595 | F12: 3.508 | G12: 6.573 | H12: 9.215 | I12: 10.417 | J12: 9.837 | K12: 8.058 | L12: 5.566 | M12: 3.912 | N12: =G12-I11 -> -2.942
A13: 1958 | B13: 2.606 | C13: -0.784 | D13: 1.157 | E13: 2.326 | F13: 3.548 | G13: 6.141 | H13: 8.54 | I13: 9.844 | J13: 9.399 | K13: 7.343 | L13: 4.817 | M13: 3.473 | N13: =G13-I12 -> -4.276
A14: 1959 | B14: 0.737 | C14: -0.672 | D14: -3.134 | E14: -0.608 | F14: 2.308 | G14: 5.834 | H14: 8.432 | I14: 9.545 | J14: 9.047 | K14: 7.44 | L14: 5.286 | M14: 3.593 | N14: =G14-I13 -> -4.01
A15: 1960 | B15: 2.416 | C15: -1.464 | D15: -2.485 | E15: 1.715 | F15: 2.948 | G15: 5.536 | H15: 8.228 | I15: 9.255 | J15: 8.545 | K15: 6.57 | L15: 4.432 | M15: 3.172 | N15: =G15-I14 -> -4.009
... A18: 1963 | B18: 2.487 | C18: 0.967 | D18: -1.646 | E18: -1.705 | F18: 2.19 | G18: 5.316 | H18: 8.047 | I18: 9.706 | J18: 9.351 | K18: 7.201 | L18: 4.546 | M18: 3.316 | N18: =G18-I17 -> -4.365
A19: 1964 | B19: 2.569 | C19: -1.247 | D19: -4.906 | E19: 0.721 | F19: 2.59 | G19: 5.397 | H19: 7.705 | I19: 8.919 | J19: 8.446 | K19: 6.528 | L19: 4.218 | M19: 2.929 | N19: =G19-I18 -> -4.309 | O19: 5228 | P19: 3589 | Q19: 2264 | R19: 470 | S19: 211 | T19: 334 | U19: 135 | V19: 49 | W19: 22 | X19: 134 | Y19: 12437
A20: 1965 | B20: 2.002 | C20: -6.29 | D20: 1.437 | E20: 1.789 | F20: 2.705 | G20: 4.925 | H20: 7.341 | I20: 9.169 | J20: 8.794 | K20: 6.69 | L20: 4.689 | M20: 3.101 | N20: =G20-I19 -> -3.994 | O20: 20407 | P20: 2123 | Q20: 2259 | R20: 1609 | S20: 284 | T20: 127 | U20: 200 | V20: 82 | W20: 30 | X20: 98 | Y20: 27218
A21: 1966 | B21: 2.431 | C21: 2.147 | D21: -5.734 | E21: 1.047 | F21: 2.479 | G21: 5.281 | H21: 8.137 | I21: 9.369 | J21: 8.712 | K21: 6.99 | L21: 4.788 | M21: 3.459 | N21: =G21-I20 -> -3.888 | O21: 14313 | P21: 8289 | Q21: 1338 | R21: 1592 | S21: 978 | T21: 175 | U21: 79 | V21: 126 | W21: 52 | X21: 82 | Y21: 27023
A22: 1967 | B22: 2.271 | C22: -1.5 | D22: 1.58 | E22: 2.061 | F22: 3.539 | G22: 5.897 | H22: 8.521 | I22: 10.118 | J22: 9.249 | K22: 7.24 | L22: 4.809 | M22: 3.271 | N22: =G22-I21 -> -3.472 | O22: 28708 | P22: 5814 | Q22: 5210 | R22: 938 | S22: 991 | T22: 613 | U22: 111 | V22: 50 | W22: 81 | X22: 87 | Y22: 42605
A23: 1968 | B23: 0.263 | C23: -2.806 | D23: 0.824 | E23: 1.87 | F23: 2.956 | G23: 5.922 | H23: 8.603 | I23: 9.821 | J23: 9.167 | K23: 7.102 | L23: 4.75 | M23: 3.11 | N23: =G23-I22 -> -4.196 | O23: 26680 | P23: 11654 | Q23: 3601 | R23: 3291 | S23: 545 | T23: 576 | U23: 359 | V23: 65 | W23: 30 | X23: 99 | Y23: 46899
A24: 1969 | B24: 2.471 | C24: 2.065 | D24: 0.742 | E24: 1.777 | F24: 3.08 | G24: 5.637 | H24: 8.483 | I24: 9.874 | J24: 9.292 | K24: 7.594 | L24: 4.931 | M24: 3.517 | N24: =G24-I23 -> -4.184 | O24: 29281 | P24: 10829 | Q24: 7190 | R24: 2349 | S24: 1853 | T24: 311 | U24: 334 | V24: 210 | W24: 38 | X24: 77 | Y24: 52473
A25: 1970 | B25: 2.485 | C25: -1.659 | D25: -0.38 | E25: 1.886 | F25: 2.969 | G25: 5.344 | H25: 7.592 | I25: 8.894 | J25: 8.726 | K25: 7.475 | L25: 5.513 | M25: 3.868 | N25: =G25-I24 -> -4.53 | O25: 20124 | P25: 11885 | Q25: 6678 | R25: 4463 | S25: 1383 | T25: 1102 | U25: 187 | V25: 201 | W25: 127 | X25: 69 | Y25: 46219
A26: 1971 | B26: 2.201 | C26: -5.261 | D26: -7.926 | E26: -3.154 | F26: 1.638 | G26: 4.306 | H26: 6.699 | I26: 8.375 | J26: 7.97 | K26: 6.465 | L26: 4.179 | M26: 2.988 | N26: =G26-I25 -> -4.588 | O26: 9676 | P26: 8163 | Q26: 7091 | R26: 3881 | S26: 2609 | T26: 812 | U26: 652 | V26: 107 | W26: 115 | X26: 106 | Y26: 33212
A27: 1972 | B27: 2.335 | C27: 1.635 | D27: -6.279 | E27: -1.809 | F27: 1.65 | G27: 4.457 | H27: 7.294 | I27: 8.913 | J27: 8.317 | K27: 6.567 | L27: 4.661 | M27: 3.346 | N27: =G27-I26 -> -3.918 | O27: 10686 | P27: 3923 | Q27: 4834 | R27: 3970 | S27: 2091 | T27: 1359 | U27: 428 | V27: 344 | W27: 56 | X27: 100 | Y27: 27792
A28: 1973 | B28: -0.156 | C28: -2.197 | D28: -3.133 | E28: 0.383 | F28: 2.262 | G28: 5.085 | H28: 7.599 | I28: 8.977 | J28: 8.535 | K28: 6.829 | L28: 4.828 | M28: 3.144 | N28: =G28-I27 -> -3.828 | O28: 28947 | P28: 4331 | Q28: 2194 | R28: 2431 | S28: 1972 | T28: 1045 | U28: 684 | V28: 215 | W28: 174 | X28: 66 | Y28: 42059
A29: 1974 | B29: 1.065 | C29: -8.782 | D29: -4.064 | E29: -0.225 | F29: 2.539 | G29: 5.279 | H29: 8.155 | I29: 9.716 | J29: 9.411 | K29: 7.222 | L29: 4.67 | M29: 3.072 | N29: =G29-I28 -> -3.698 | O29: 21457 | P29: 11726 | Q29: 2336 | R29: 1035 | S29: 1059 | T29: 862 | U29: 459 | V29: 301 | W29: 95 | X29: 101 | Y29: 39433
A30: 1975 | B30: 2.19 | C30: -6.277 | D30: -4.25 | E30: -2.053 | F30: 1.804 | G30: 4.461 | H30: 7.267 | I30: 8.627 | J30: 8.187 | K30: 6.422 | L30: 3.96 | M30: 2.558 | N30: =G30-I29 -> -5.255 | O30: 18171 | P30: 8692 | Q30: 5920 | R30: 972 | S30: 433 | T30: 447 | U30: 367 | V30: 196 | W30: 128 | X30: 82 | Y30: 35406
... A67: 2012 | B67: -6.942 | C67: -4.238 | D67: -9.979 | E67: -3.375 | F67: -0.38 | G67: 3.091 | H67: 6.231 | I67: 8.487 | J67: 7.957 | K67: 6.23 | L67: 3.168 | M67: 0.088 | N67: =G67-I66 -> -5.556 | O67: 17451 | P67: 7570 | Q67: 4950 | R67: 8193 | S67: 1080 | T67: 1551 | U67: 359 | V67: 86 | W67: 61 | X67: 226 | Y67: 41527
A68: 2013 | B68: -0.833 | C68: -5.187 | D68: -3.727 | E68: -1.618 | F68: 0.556 | G68: 4.595 | H68: 7.677 | I68: 10.426 | J68: 9.519 | K68: 7.034 | L68: 5.632 | M68: 3.21 | N68: =G68-I67 -> -3.892
A69: 2014 | B69: 2.383 | C69: 1.659 | D69: 0.475 | E69: 1.354 | F69: 3.905 | G69: 6.587 | H69: 10.251 | I69: 12.719 | J69: 11.907 | K69: 8.481 | L69: 5.665 | M69: 4.824 | N69: =G69-I68 -> -3.839
A70: 2015 | B70: 3.227 | C70: 1.655 | D70: 1.535 | E70: 1.696 | F70: 3.536 | G70: 6.763 | H70: 10.077 | I70: 11.687 | J70: 10.683 | K70: 8.576 | L70: 6.282 | M70: 3.951 | N70: =G70-I69 -> -5.956
A71: 2016 | B71: 2.998 | C71: 2.671 | D71: 2.547 | E71: 2.861 | F71: 5.149 | G71: 8.497 | H71: 11.796 | I71: 12.997 | J71: 12.298 | K71: 9.706 | L71: 7.142 | M71: 3.174 | N71: =G71-I70 -> -3.19
A72: 2017 | B72: 1.996 | C72: 0.228 | D72: -1.295 | E72: 0.044 | F72: 2.815 | G72: 6.391 | H72: 8.877 | I72: 10.67 | J72: 9.0316 | K72: 7.593 | L72: 6.005 | M72: 3.093 | N72: =G72-I71 -> -6.606
A73: 2018 | B73: 1.516 | C73: 0.814 | D73: 1.457 | E73: 2.058 | F73: 3.62 | G73: 6.608 | H73: 9.572 | N73: =G73-I72 -> -4.062
E74: =180-161.2 -> 18.8 | F74: =180-166.9 -> 13.1 | O74: 22017.163 | P74: 8873.3265 | Q74: 5460.6735 | R74: 3628 | S74: 2226.3061 | T74: 1347.1224 | U74: 759.4898 | V74: 424.12245 | W74: 237.4898 | X74: 304.93878 | Y74: 45278.51
E75: =180+E74 -> 198.8 | F75: =180+F74 -> 193.1 | N75: =AVERAGE(N4:N69) -> -4.5676515 | O75: 13145.997 | P75: 5390.0036 | Q75: 3438.1315 | R75: 2526.5518 | S75: 1713.9165 | T75: 1140.6354 | U75: 711.55391 | V75: 427.51636 | W75: 251.4677 | X75: 263.56328 | Y75: 15425.004
G77: =AVERAGE(G5:G71) -> 5.1868209 | I77: =AVERAGE(I5:I71) -> 9.8049851

Sheet 2017 Ianelli
U1: age-3 (yr) | V1: age-2 | W1: age-1
B2: 1 | C2: 2 | D2: 3 | E2: 4 | F2: 5 | G2: 6 | H2: 7 | I2: 8 | J2: 9 | K2: 10+ | L2: TC | N2: Year | O2: age-1 | P2: Age-2 | R2: Age-4 | S2: Age-5 | T2: Age-6 | U2: TC index (yr-2) | V2: TC index2 | W2: TC index3 | X2: TC index4 | Y2: TCindex5 | Z2: TCindex6
Q4: Age-3 (yr)
N5: 1960
L6: ='All data'!N16 -> -3.912 | N6: 1961
L7: ='All data'!N17 -> -4.068 | N7: 1962 | U7: =(L7-AVERAGE($L$6:$L$63))/STDEV($L$6:$L$63) -> 0.44909183
L8: ='All data'!N18 -> -4.365 | N8: 1963 | U8: =(L8-AVERAGE($L$6:$L$63))/STDEV($L$6:$L$63) -> 0.18829367 | V8: 0.44909183
A9: 1964 | B9: ='pollock Model 2017 data'!P3 -> 6.43 | C9: ='pollock Model 2017 data'!Q3 -> 3.46 | D9: ='pollock Model 2017 data'!R3 -> 2.19 | E9: ='pollock Model 2017 data'!S3 -> 0.47 | F9: ='pollock Model 2017 data'!T3 -> 0.2 | G9: ='pollock Model 2017 data'!U3 -> 0.39 | H9: ='pollock Model 2017 data'!V3 -> 0.18 | I9: ='pollock Model 2017 data'!W3 -> 0.06 | ... K9: ='pollock Model 2017 data'!Y3 -> 0.22 | L9: ='All data'!N19 -> -4.309 | N9: =A9 -> 1964 | O9: =(B9-AVERAGE($B$9:$B$62))/STDEV($B$9:$B$62) -> -1.2061573 | P9: =(C9-AVERAGE($C$9:$C$62))/STDEV($C$9:$C$62) -> -1.0252999 | Q9: =(D9-AVERAGE($D$9:$D$62))/STDEV($D$9:$D$62) -> -0.97632215 | R9: =(E9-AVERAGE($E$9:$E$62))/STDEV($E$9:$E$62) -> -1.2748257 | S9: =(F9-AVERAGE($F$9:$F$62))/STDEV($F$9:$F$62) -> -1.2159536 | T9: =(G9-AVERAGE($G$9:$G$62))/STDEV($G$9:$G$62) -> -0.88326785 | U9: =(L9-AVERAGE($L$6:$L$63))/STDEV($L$6:$L$63) -> 0.23746773 | V9: 0.18829367 | W9: 0.44909183
A10: 1965 | B10: ='pollock Model 2017 data'!P4 -> 21.16 | C10: ='pollock Model 2017 data'!Q4 -> 2.61 | D10: ='pollock Model 2017 data'!R4 -> 2.18 | E10: ='pollock Model 2017 data'!S4 -> 1.55 | F10: ='pollock Model 2017 data'!T4 -> 0.29 | G10: ='pollock Model 2017 data'!U4 -> 0.13 | H10: ='pollock Model 2017 data'!V4 -> 0.25 | I10: ='pollock Model 2017 data'!W4 -> 0.11 | ... K10: ='pollock Model 2017 data'!Y4 -> 0.16 | L10: ='All data'!N20 -> -3.994 | N10: =A10 -> 1965 | O10: =(B10-AVERAGE($B$9:$B$62))/STDEV($B$9:$B$62) -> -0.10743806 | P10: =(C10-AVERAGE($C$9:$C$62))/STDEV($C$9:$C$62) -> -1.1798525 | Q10: =(D10-AVERAGE($D$9:$D$62))/STDEV($D$9:$D$62) -> -0.97915968 | R10: =(E10-AVERAGE($E$9:$E$62))/STDEV($E$9:$E$62) -> -0.86042383 | S10: =(F10-AVERAGE($F$9:$F$62))/STDEV($F$9:$F$62) -> -1.1649874 | T10: =(G10-AVERAGE($G$9:$G$62))/STDEV($G$9:$G$62) -> -1.1229486 | U10: =(L10-AVERAGE($L$6:$L$63))/STDEV($L$6:$L$63) -> 0.51407184 | V10: 0.23746773 | W10: 0.18829367 | X10: 0.44909183
A11: 1966 | B11: ='pollock Model 2017 data'!P5 -> 15.16 | C11: ='pollock Model 2017 data'!Q5 -> 8.59 | D11: ='pollock Model 2017 data'!R5 -> 1.64 | E11: ='pollock Model 2017 data'!S5 -> 1.53 | F11: ='pollock Model 2017 data'!T5 -> 0.96 | G11: ='pollock Model 2017 data'!U5 -> 0.18 | H11: ='pollock Model 2017 data'!V5 -> 0.08 | I11: ='pollock Model 2017 data'!W5 -> 0.16 | ... K11: ='pollock Model 2017 data'!Y5 -> 0.13 | L11: ='All data'!N21 -> -3.888 | N11: =A11 -> 1966 | O11: =(B11-AVERAGE($B$9:$B$62))/STDEV($B$9:$B$62) -> -0.55498155 | P11: =(C11-AVERAGE($C$9:$C$62))/STDEV($C$9:$C$62) -> -0.092529525 | Q11: =(D11-AVERAGE($D$9:$D$62))/STDEV($D$9:$D$62) -> -1.1323866 | R11: =(E11-AVERAGE($E$9:$E$62))/STDEV($E$9:$E$62) -> -0.86809794 | S11: =(F11-AVERAGE($F$9:$F$62))/STDEV($F$9:$F$62) -> -0.78557212 | T11: =(G11-AVERAGE($G$9:$G$62))/STDEV($G$9:$G$62) -> -1.0768561 | U11: =(L11-AVERAGE($L$6:$L$63))/STDEV($L$6:$L$63) -> 0.60715132 | V11: 0.51407184 | W11: 0.23746773 | X11: 0.18829367 | Y11: 0.44909183
A12: 1967 | B12: ='pollock Model 2017 data'!P6 -> 25.65 | C12: ='pollock Model 2017 data'!Q6 -> 6.15 | D12: ='pollock Model 2017 data'!R6 -> 5.4 | E12: ='pollock Model 2017 data'!S6 -> 1.15 | F12: ='pollock Model 2017 data'!T6 -> 0.97 | G12: ='pollock Model 2017 data'!U6 -> 0.61 | H12: ='pollock Model 2017 data'!V6 -> 0.12 | I12: ='pollock Model 2017 data'!W6 -> 0.05 | ... K12: ='pollock Model 2017 data'!Y6 -> 0.13 | L12: ='All data'!N22 -> -3.472 | N12: =A12 -> 1967 | O12: =(B12-AVERAGE($B$9:$B$62))/STDEV($B$9:$B$62) -> 0.22747365 | P12: =(C12-AVERAGE($C$9:$C$62))/STDEV($C$9:$C$62) -> -0.53618638 | Q12: =(D12-AVERAGE($D$9:$D$62))/STDEV($D$9:$D$62) -> -0.065473487 | R12: =(E12-AVERAGE($E$9:$E$62))/STDEV($E$9:$E$62) -> -1.013906 | S12: =(F12-AVERAGE($F$9:$F$62))/STDEV($F$9:$F$62) -> -0.7799092 | T12: =(G12-AVERAGE($G$9:$G$62))/STDEV($G$9:$G$62) -> -0.68046109 | U12: =(L12-AVERAGE($L$6:$L$63))/STDEV($L$6:$L$63) -> 0.97244437 | V12: 0.60715132 | W12: 0.51407184 | X12: 0.23746773 | Y12: 0.18829367 | Z12: 0.44909183
A13: 1968 | B13: ='pollock Model 2017 data'!P7 -> 22.19 | C13: ='pollock Model 2017 data'!Q7 -> 10.39 | D13: ='pollock Model 2017 data'!R7 -> 3.81 | E13: ='pollock Model 2017 data'!S7 -> 3.52 | F13: ='pollock Model 2017 data'!T7 -> 0.67 | G13: ='pollock Model 2017 data'!U7 -> 0.56 | H13: ='pollock Model 2017 data'!V7 -> 0.36 | I13: ='pollock Model 2017 data'!W7 -> 0.07 | ... K13: ='pollock Model 2017 data'!Y7 -> 0.14 | L13: ='All data'!N23 -> -4.196 | N13: =A13 -> 1968 | O13: =(B13-AVERAGE($B$9:$B$62))/STDEV($B$9:$B$62) -> -0.030609764 | P13: =(C13-AVERAGE($C$9:$C$62))/STDEV($C$9:$C$62) -> 0.23475832 | Q13: =(D13-AVERAGE($D$9:$D$62))/STDEV($D$9:$D$62) -> -0.51664152 | R13: =(E13-AVERAGE($E$9:$E$62))/STDEV($E$9:$E$62) -> -0.10452419 | S13: =(F13-AVERAGE($F$9:$F$62))/STDEV($F$9:$F$62) -> -0.94979665 | T13: =(G13-AVERAGE($G$9:$G$62))/STDEV($G$9:$G$62) -> -0.72655353 | U13: =(L13-AVERAGE($L$6:$L$63))/STDEV($L$6:$L$63) -> 0.33669397 | V13: 0.97244437 | W13: 0.60715132 | X13: 0.51407184 | Y13: 0.23746773 | Z13: 0.18829367
A14: 1969 | B14: ='pollock Model 2017 data'!P8 -> 26.18 | C14: ='pollock Model 2017 data'!Q8 -> 8.98 | D14: ='pollock Model 2017 data'!R8 -> 6.42 | E14: ='pollock Model 2017 data'!S8 -> 2.49 | F14: ='pollock Model 2017 data'!T8 -> 2.04 | G14: ='pollock Model 2017 data'!U8 -> 0.39 | H14: ='pollock Model 2017 data'!V8 -> 0.33 | I14: ='pollock Model 2017 data'!W8 -> 0.21 | ... K14: ='pollock Model 2017 data'!Y8 -> 0.1 | L14: ='All data'!N24 -> -4.184 | N14: =A14 -> 1969 | O14: =(B14-AVERAGE($B$9:$B$62))/STDEV($B$9:$B$62) -> 0.26700665 | P14: =(C14-AVERAGE($C$9:$C$62))/STDEV($C$9:$C$62) -> -0.02161716 | Q14: =(D14-AVERAGE($D$9:$D$62))/STDEV($D$9:$D$62) -> 0.22395506 | R14: =(E14-AVERAGE($E$9:$E$62))/STDEV($E$9:$E$62) -> -0.49974076 | S14: =(F14-AVERAGE($F$9:$F$62))/STDEV($F$9:$F$62) -> -0.17397733 | T14: =(G14-AVERAGE($G$9:$G$62))/STDEV($G$9:$G$62) -> -0.88326785 | U14: =(L14-AVERAGE($L$6:$L$63))/STDEV($L$6:$L$63) -> 0.34723127 | V14: 0.33669397 | W14: 0.97244437 | X14: 0.60715132 | Y14: 0.51407184 | Z14: 0.23746773
A15: 1970 | B15: ='pollock Model 2017 data'!P9 -> 23.52 | C15: ='pollock Model 2017 data'!Q9 -> 10.59 | D15: ='pollock Model 2017 data'!R9 -> 5.52 | E15: ='pollock Model 2017 data'!S9 -> 4.06 | F15: ='pollock Model 2017 data'!T9 -> 1.46 | G15: ='pollock Model 2017 data'!U9 -> 1.21 | H15: ='pollock Model 2017 data'!V9 -> 0.23 | I15: ='pollock Model 2017 data'!W9 -> 0.2 | ... K15: ='pollock Model 2017 data'!Y9 -> 0.08 | L15: ='All data'!N25 -> -4.53 | N15: =A15 -> 1970 | O15: =(B15-AVERAGE($B$9:$B$62))/STDEV($B$9:$B$62) -> 0.068595709 | P15: =(C15-AVERAGE($C$9:$C$62))/STDEV($C$9:$C$62) -> 0.27112363 | Q15: =(D15-AVERAGE($D$9:$D$62))/STDEV($D$9:$D$62) -> -0.03142307 | R15: =(E15-AVERAGE($E$9:$E$62))/STDEV($E$9:$E$62) -> 0.10267672 | S15: =(F15-AVERAGE($F$9:$F$62))/STDEV($F$9:$F$62) -> -0.50242638 | T15: =(G15-AVERAGE($G$9:$G$62))/STDEV($G$9:$G$62) -> -0.12735172 | U15: =(L15-AVERAGE($L$6:$L$63))/STDEV($L$6:$L$63) -> 0.043405801 | V15: 0.34723127 | W15: 0.33669397 | X15: 0.97244437 | Y15: 0.60715132 | Z15: 0.51407184
A16: 1971 | B16: ='pollock Model 2017 data'!P10 -> 14.46 | C16: ='pollock Model 2017 data'!Q10 -> 9.47 | D16: ='pollock Model 2017 data'!R10 -> 6.36 | E16: ='pollock Model 2017 data'!S10 -> 3.29 | F16: ='pollock Model 2017 data'!T10 -> 2.32 | G16: ='pollock Model 2017 data'!U10 -> 0.81 | H16: ='pollock Model 2017 data'!V10 -> 0.67 | I16: ='pollock Model 2017 data'!W10 -> 0.13 | ... K16: ='pollock Model 2017 data'!Y10 -> 0.1 | L16: ='All data'!N26 -> -4.588 | N16: =A16 -> 1971 | O16: =(B16-AVERAGE($B$9:$B$62))/STDEV($B$9:$B$62) -> -0.60719496 | P16: =(C16-AVERAGE($C$9:$C$62))/STDEV($C$9:$C$62) -> 0.067477863 | Q16: =(D16-AVERAGE($D$9:$D$62))/STDEV($D$9:$D$62) -> 0.20692985 | R16: =(E16-AVERAGE($E$9:$E$62))/STDEV($E$9:$E$62) -> -0.19277644 | S16: =(F16-AVERAGE($F$9:$F$62))/STDEV($F$9:$F$62) -> -0.015415712 | T16: =(G16-AVERAGE($G$9:$G$62))/STDEV($G$9:$G$62) -> -0.4960913 | U16: =(L16-AVERAGE($L$6:$L$63))/STDEV($L$6:$L$63) -> -0.0075244796 | V16: 0.043405801 | W16: 0.34723127 | X16: 0.33669397 | Y16: 0.97244437 | Z16: 0.60715132
A17: 1972 | B17: ='pollock Model 2017 data'!P11 -> 11.83 | C17: ='pollock Model 2017 data'!Q11 -> 5.8 | D17: ='pollock Model 2017 data'!R11 -> 5.55 | E17: ='pollock Model 2017 data'!S11 -> 3.57 | F17: ='pollock Model 2017 data'!T11 -> 1.73 | G17: ='pollock Model 2017 data'!U11 -> 1.15 | H17: ='pollock Model 2017 data'!V11 -> 0.4 | I17: ='pollock Model 2017 data'!W11 -> 0.33 | ... K17: ='pollock Model 2017 data'!Y11 -> 0.09 | L17: ='All data'!N27 -> -3.918 | N17: =A17 -> 1972 | O17: =(B17-AVERAGE($B$9:$B$62))/STDEV($B$9:$B$62) -> -0.80336819 | P17: =(C17-AVERAGE($C$9:$C$62))/STDEV($C$9:$C$62) -> -0.59982568 | Q17: =(D17-AVERAGE($D$9:$D$62))/STDEV($D$9:$D$62) -> -0.022910466 | R17: =(E17-AVERAGE($E$9:$E$62))/STDEV($E$9:$E$62) -> -0.085338923 | S17: =(F17-AVERAGE($F$9:$F$62))/STDEV($F$9:$F$62) -> -0.34952768 | T17: =(G17-AVERAGE($G$9:$G$62))/STDEV($G$9:$G$62) -> -0.18266266 | U17: =(L17-AVERAGE($L$6:$L$63))/STDEV($L$6:$L$63) -> 0.58080807 | V17: -0.0075244796 | W17: 0.043405801 | X17: 0.34723127 | Y17: 0.33669397 | Z17: 0.97244437
A18: 1973 | B18: ='pollock Model 2017 data'!P12 -> 26.95 | C18: ='pollock Model 2017 data'!Q12 -> 4.75 | D18: ='pollock Model 2017 data'!R12 -> 3.3 | E18: ='pollock Model 2017 data'!S12 -> 2.89 | F18: ='pollock Model 2017 data'!T12 -> 1.73 | G18: ='pollock Model 2017 data'!U12 -> 0.82 | H18: ='pollock Model 2017 data'!V12 -> 0.55 | I18: ='pollock Model 2017 data'!W12 -> 0.19 | ... K18: ='pollock Model 2017 data'!Y12 -> 0.06 | L18: ='All data'!N28 -> -3.828 | N18: =A18 -> 1973 | O18: =(B18-AVERAGE($B$9:$B$62))/STDEV($B$9:$B$62) -> 0.3244414 | P18: =(C18-AVERAGE($C$9:$C$62))/STDEV($C$9:$C$62) -> -0.79074359 | Q18: =(D18-AVERAGE($D$9:$D$62))/STDEV($D$9:$D$62) -> -0.66135579 | R18: =(E18-AVERAGE($E$9:$E$62))/STDEV($E$9:$E$62) -> -0.3462586 | S18: =(F18-AVERAGE($F$9:$F$62))/STDEV($F$9:$F$62) -> -0.34952768 | T18: =(G18-AVERAGE($G$9:$G$62))/STDEV($G$9:$G$62) -> -0.48687281 | U18: =(L18-AVERAGE($L$6:$L$63))/STDEV($L$6:$L$63) -> 0.65983782 | V18: 0.58080807 | W18: -0.0075244796 | X18: 0.043405801 | Y18: 0.34723127 | Z18: 0.33669397
A19: 1974 | B19: ='pollock Model 2017 data'!P13 -> 19.77 | C19: ='pollock Model 2017 data'!Q13 -> 10.85 | D19: ='pollock Model 2017 data'!R13 -> 2.62 | E19: ='pollock Model 2017 data'!S13 -> 1.59 | F19: ='pollock Model 2017 data'!T13 -> 1.29 | G19: ='pollock Model 2017 data'!U13 -> 0.76 | H19: ='pollock Model 2017 data'!V13 -> 0.36 | I19: ='pollock Model 2017 data'!W13 -> 0.24 | ... K19: ='pollock Model 2017 data'!Y13 -> 0.08 | L19: ='All data'!N29 -> -3.698 | N19: =A19 -> 1974 | O19: =(B19-AVERAGE($B$9:$B$62))/STDEV($B$9:$B$62) -> -0.21111897 | P19: =(C19-AVERAGE($C$9:$C$62))/STDEV($C$9:$C$62) -> 0.31839854 | Q19: =(D19-AVERAGE($D$9:$D$62))/STDEV($D$9:$D$62) -> -0.85430815 | R19: =(E19-AVERAGE($E$9:$E$62))/STDEV($E$9:$E$62) -> -0.84507562 | S19: =(F19-AVERAGE($F$9:$F$62))/STDEV($F$9:$F$62) -> -0.59869593 | T19: =(G19-AVERAGE($G$9:$G$62))/STDEV($G$9:$G$62) -> -0.54218375 | U19: =(L19-AVERAGE($L$6:$L$63))/STDEV($L$6:$L$63) -> 0.7739919 | V19: 0.65983782 | W19: 0.58080807 | X19: -0.0075244796 | Y19: 0.043405801 | Z19: 0.34723127
A20: 1975 | B20: ='pollock Model 2017 data'!P14 -> 16.77 | C20: ='pollock Model 2017 data'!Q14 -> 7.97 | D20: ='pollock Model 2017 data'!R14 -> 5.76 | E20: ='pollock Model 2017 data'!S14 -> 1.12 | F20: ='pollock Model 2017 data'!T14 -> 0.67 | G20: ='pollock Model 2017 data'!U14 -> 0.54 | H20: ='pollock Model 2017 data'!V14 -> 0.32 | I20: ='pollock Model 2017 data'!W14 -> 0.15 | ... K20: ='pollock Model 2017 data'!Y14 -> 0.06 | L20: ='All data'!N30 -> -5.255 | N20: =A20 -> 1975 | O20: =(B20-AVERAGE($B$9:$B$62))/STDEV($B$9:$B$62) -> -0.43489071 | P20: =(C20-AVERAGE($C$9:$C$62))/STDEV($C$9:$C$62) -> -0.205262 | Q20: =(D20-AVERAGE($D$9:$D$62))/STDEV($D$9:$D$62) -> 0.036677764 | R20: =(E20-AVERAGE($E$9:$E$62))/STDEV($E$9:$E$62) -> -1.0254172 | S20: =(F20-AVERAGE($F$9:$F$62))/STDEV($F$9:$F$62) -> -0.94979665 | T20: =(G20-AVERAGE($G$9:$G$62))/STDEV($G$9:$G$62) -> -0.74499051 | U20: =(L20-AVERAGE($L$6:$L$63))/STDEV($L$6:$L$63) -> -0.59322271 | V20: 0.7739919 | W20: 0.65983782 | X20: 0.58080807 | Y20: -0.0075244796 | Z20: 0.043405801
A21: 1976 | B21: ='pollock Model 2017 data'!P15 -> 12.9 | C21: ='pollock Model 2017 data'!Q15 -> 6.78 | D21: ='pollock Model 2017 data'!R15 -> 4.49 | E21: ='pollock Model 2017 data'!S15 -> 2.59 | F21: ='pollock Model 2017 data'!T15 -> 0.51 | G21: ='pollock Model 2017 data'!U15 -> 0.31 | H21: ='pollock Model 2017 data'!V15 -> 0.25 | I21: ='pollock Model 2017 data'!W15 -> 0.15 | ... K21: ='pollock Model 2017 data'!Y15 -> 0.07 | L21: ='All data'!N31 -> -4.08 | N21: =A21 -> 1976 | O21: =(B21-AVERAGE($B$9:$B$62))/STDEV($B$9:$B$62) -> -0.72355626 | P21: =(C21-AVERAGE($C$9:$C$62))/STDEV($C$9:$C$62) -> -0.42163563 | Q21: =(D21-AVERAGE($D$9:$D$62))/STDEV($D$9:$D$62) -> -0.32368915 | R21: =(E21-AVERAGE($E$9:$E$62))/STDEV($E$9:$E$62) -> -0.46137022 | S21: =(F21-AVERAGE($F$9:$F$62))/STDEV($F$9:$F$62) -> -1.0404033 | T21: =(G21-AVERAGE($G$9:$G$62))/STDEV($G$9:$G$62) -> -0.95701577 | U21: =(L21-AVERAGE($L$6:$L$63))/STDEV($L$6:$L$63) -> 0.43855453 | V21: -0.59322271 | W21: 0.7739919 | X21: 0.65983782 | Y21: 0.58080807 | Z21: -0.0075244796
A22: 1977 | B22: ='pollock Model 2017 data'!P16 -> 13.38 | C22: ='pollock Model 2017 data'!Q16 -> 5.22 | D22: ='pollock Model 2017 data'!R16 -> 3.91 | E22: ='pollock Model 2017 data'!S16 -> 2.22 | F22: ='pollock Model 2017 data'!T16 -> 1.21 | G22: ='pollock Model 2017 data'!U16 -> 0.24 | H22: ='pollock Model 2017 data'!V16 -> 0.15 | I22: ='pollock Model 2017 data'!W16 -> 0.12 | ... K22: ='pollock Model 2017 data'!Y16 -> 0.06 | L22: ='All data'!N32 -> -2.706 | N22: =A22 -> 1977 | O22: =(B22-AVERAGE($B$9:$B$62))/STDEV($B$9:$B$62) -> -0.68775279 | P22: =(C22-AVERAGE($C$9:$C$62))/STDEV($C$9:$C$62) -> -0.70528509 | Q22: =(D22-AVERAGE($D$9:$D$62))/STDEV($D$9:$D$62) -> -0.48826617 | R22: =(E22-AVERAGE($E$9:$E$62))/STDEV($E$9:$E$62) -> -0.60334121 | S22: =(F22-AVERAGE($F$9:$F$62))/STDEV($F$9:$F$62) -> -0.64399925 | T22: =(G22-AVERAGE($G$9:$G$62))/STDEV($G$9:$G$62) -> -1.0215452 | U22: =(L22-AVERAGE($L$6:$L$63))/STDEV($L$6:$L$63) -> 1.6450753 | V22: 0.43855453 | W22: -0.59322271 | X22: 0.7739919 | Y22: 0.65983782 | Z22: 0.58080807
A23: 1978 | B23: ='pollock Model 2017 data'!P17 -> 24.61 | C23: ='pollock Model 2017 data'!Q17 -> 5.42 | D23: ='pollock Model 2017 data'!R17 -> 3.05 | E23: ='pollock Model 2017 data'!S17 -> 2.13 | F23: ='pollock Model 2017 data'!T17 -> 1.12 | G23: ='pollock Model 2017 data'!U17 -> 0.6 | H23: ='pollock Model 2017 data'!V17 -> 0.12 | I23: ='pollock Model 2017 data'!W17 -> 0.07 | ... K23: ='pollock Model 2017 data'!Y17 -> 0.06 | L23: ='All data'!N33 -> -4.676 | N23: =A23 -> 1978 | O23: =(B23-AVERAGE($B$9:$B$62))/STDEV($B$9:$B$62) -> 0.14989944 | P23: =(C23-AVERAGE($C$9:$C$62))/STDEV($C$9:$C$62) -> -0.66891978 | Q23: =(D23-AVERAGE($D$9:$D$62))/STDEV($D$9:$D$62) -> -0.73229416 | R23: =(E23-AVERAGE($E$9:$E$62))/STDEV($E$9:$E$62) -> -0.6378747 | S23: =(F23-AVERAGE($F$9:$F$62))/STDEV($F$9:$F$62) -> -0.69496548 | T23: =(G23-AVERAGE($G$9:$G$62))/STDEV($G$9:$G$62) -> -0.68967958 | U23: =(L23-AVERAGE($L$6:$L$63))/STDEV($L$6:$L$63) -> -0.084798009 | V23: 1.6450753 | W23: 0.43855453 | X23: -0.59322271 | Y23: 0.7739919 | Z23: 0.65983782
... A58: 2013 | B58: ='pollock Model 2017 data'!P52 -> 60.22 | C58: ='pollock Model 2017 data'!Q52 -> 4.5 | D58: ='pollock Model 2017 data'!R52 -> 3.31 | E58: ='pollock Model 2017 data'!S52 -> 4.05 | F58: ='pollock Model 2017 data'!T52 -> 6.7 | G58: ='pollock Model 2017 data'!U52 -> 1.2 | H58: ='pollock Model 2017 data'!V52 -> 0.74 | I58: ='pollock Model 2017 data'!W52 -> 0.21 | ... K58: ='pollock Model 2017 data'!Y52 -> 0.13 | L58: ='All data'!N68 -> -3.892 | N58: =A58 -> 2013 | O58: =(B58-AVERAGE($B$9:$B$62))/STDEV($B$9:$B$62) -> 2.80607 | P58: =(C58-AVERAGE($C$9:$C$62))/STDEV($C$9:$C$62) -> -0.83620023 | Q58: =(D58-AVERAGE($D$9:$D$62))/STDEV($D$9:$D$62) -> -0.65851825 | R58: =(E58-AVERAGE($E$9:$E$62))/STDEV($E$9:$E$62) -> 0.098839669 | S58: =(F58-AVERAGE($F$9:$F$62))/STDEV($F$9:$F$62) -> 2.4649409 | T58: =(G58-AVERAGE($G$9:$G$62))/STDEV($G$9:$G$62) -> -0.13657021 | U58: =(L58-AVERAGE($L$6:$L$63))/STDEV($L$6:$L$63) -> 0.60363889 | V58: -0.8575333 | W58: 0.30596018 | X58: -1.2491696 | Y58: -0.80923735 | Z58: -2.2510912
A59: 2014 | B59: ='pollock Model 2017 data'!P53 -> 39.88 | C59: ='pollock Model 2017 data'!Q53 -> 24.48 | D59: ='pollock Model 2017 data'!R53 -> 2.86 | E59: ='pollock Model 2017 data'!S53 -> 2.39 | F59: ='pollock Model 2017 data'!T53 -> 2.7 | G59: ='pollock Model 2017 data'!U53 -> 4.13 | H59: ='pollock Model 2017 data'!V53 -> 0.72 | I59: ='pollock Model 2017 data'!W53 -> 0.4 | ... K59: ='pollock Model 2017 data'!Y53 -> 0.09 | L59: ='All data'!N69 -> -3.839 | N59: 2014 | O59: =(B59-AVERAGE($B$9:$B$62))/STDEV($B$9:$B$62) -> 1.2888976 | P59: =(C59-AVERAGE($C$9:$C$62))/STDEV($C$9:$C$62) -> 2.7966948 | Q59: =(D59-AVERAGE($D$9:$D$62))/STDEV($D$9:$D$62) -> -0.78620732 | R59: =(E59-AVERAGE($E$9:$E$62))/STDEV($E$9:$E$62) -> -0.5381113 | S59: =(F59-AVERAGE($F$9:$F$62))/STDEV($F$9:$F$62) -> 0.19977505 | T59: =(G59-AVERAGE($G$9:$G$62))/STDEV($G$9:$G$62) -> 2.5644472 | U59: =(L59-AVERAGE($L$6:$L$63))/STDEV($L$6:$L$63) -> 0.65017863 | V59: 0.60363889 | W59: -0.8575333 | X59: 0.30596018 | Y59: -1.2491696 | Z59: -0.80923735
A60: 2015 | B60: ='pollock Model 2017 data'!P54 -> 17.26 | C60: ='pollock Model 2017 data'!Q54 -> 16.21 | D60: ='pollock Model 2017 data'!R54 -> 15.59 | E60: ='pollock Model 2017 data'!S54 -> 2.08 | F60: ='pollock Model 2017 data'!T54 -> 1.62 | G60: ='pollock Model 2017 data'!U54 -> 1.65 | H60: ='pollock Model 2017 data'!V54 -> 2.39 | I60: ='pollock Model 2017 data'!W54 -> 0.38 | ... K60: ='pollock Model 2017 data'!Y54 -> 0.1 | L60: ='All data'!N70 -> -5.956 | N60: 2015 | O60: =(B60-AVERAGE($B$9:$B$62))/STDEV($B$9:$B$62) -> -0.39834133 | P60: =(C60-AVERAGE($C$9:$C$62))/STDEV($C$9:$C$62) -> 1.292989 | Q60: =(D60-AVERAGE($D$9:$D$62))/STDEV($D$9:$D$62) -> 2.8259744 | R60: =(E60-AVERAGE($E$9:$E$62))/STDEV($E$9:$E$62) -> -0.65705997 | S60: =(F60-AVERAGE($F$9:$F$62))/STDEV($F$9:$F$62) -> -0.41181974 | T60: =(G60-AVERAGE($G$9:$G$62))/STDEV($G$9:$G$62) -> 0.27826181 | U60: =(L60-AVERAGE($L$6:$L$63))/STDEV($L$6:$L$63) -> -1.2087766 | V60: 0.65017863 | W60: 0.60363889 | X60: -0.8575333 | Y60: 0.30596018 | Z60: -1.2491696
A61: 2016 | B61: ='pollock Model 2017 data'!P55 -> 18.24 | C61: ='pollock Model 2017 data'!Q55 -> 7.02 | D61: ='pollock Model 2017 data'!R55 -> 10.32 | E61: ='pollock Model 2017 data'!S55 -> 11.02 | F61: ='pollock Model 2017 data'!T55 -> 1.37 | G61: ='pollock Model 2017 data'!U55 -> 1 | H61: ='pollock Model 2017 data'!V55 -> 0.9 | I61: ='pollock Model 2017 data'!W55 -> 1.31 | ... K61: ='pollock Model 2017 data'!Y55 -> 0.16 | L61: ='All data'!N71 -> -3.19 | N61: 2016 | O61: =(B61-AVERAGE($B$9:$B$62))/STDEV($B$9:$B$62) -> -0.32524256 | P61: =(C61-AVERAGE($C$9:$C$62))/STDEV($C$9:$C$62) -> -0.37799725 | Q61: =(D61-AVERAGE($D$9:$D$62))/STDEV($D$9:$D$62) -> 1.3305936 | R61: =(E61-AVERAGE($E$9:$E$62))/STDEV($E$9:$E$62) -> 2.7732663 | S61: =(F61-AVERAGE($F$9:$F$62))/STDEV($F$9:$F$62) -> -0.55339261 | T61: =(G61-AVERAGE($G$9:$G$62))/STDEV($G$9:$G$62) -> -0.32094 | U61: =(L61-AVERAGE($L$6:$L$63))/STDEV($L$6:$L$63) -> 1.2200709 | V61: -1.2087766 | W61: 0.65017863 | X61: 0.60363889 | Y61: -0.8575333 | Z61: 0.30596018
A62: 2017 | B62: ='pollock Model 2017 data'!P56 -> 18.47 | C62: ='pollock Model 2017 data'!Q56 -> 7.42 | D62: ='pollock Model 2017 data'!R56 -> 4.47 | E62: ='pollock Model 2017 data'!S56 -> 7.56 | F62: ='pollock Model 2017 data'!T56 -> 6.98 | G62: ='pollock Model 2017 data'!U56 -> 0.88 | H62: ='pollock Model 2017 data'!V56 -> 0.59 | I62: ='pollock Model 2017 data'!W56 -> 0.52 | ... K62: ='pollock Model 2017 data'!Y56 -> 0.22 | L62: ='All data'!N72 -> -6.606 | N62: 2017 | O62: =(B62-AVERAGE($B$9:$B$62))/STDEV($B$9:$B$62) -> -0.30808673 | P62: =(C62-AVERAGE($C$9:$C$62))/STDEV($C$9:$C$62) -> -0.30526662 | Q62: =(D62-AVERAGE($D$9:$D$62))/STDEV($D$9:$D$62) -> -0.32936422 | R62: =(E62-AVERAGE($E$9:$E$62))/STDEV($E$9:$E$62) -> 1.4456456 | S62: =(F62-AVERAGE($F$9:$F$62))/STDEV($F$9:$F$62) -> 2.6235026 | T62: =(G62-AVERAGE($G$9:$G$62))/STDEV($G$9:$G$62) -> -0.43156187 | U62: =(L62-AVERAGE($L$6:$L$63))/STDEV($L$6:$L$63) -> -1.779547 | V62: 1.2200709 | W62: -1.2087766 | X62: 0.65017863 | Y62: 0.60363889 | Z62: -0.8575333
L63: ='All data'!N73 -> -4.062 | N63: 2018 | U63: =(L63-AVERAGE($L$6:$L$63))/STDEV($L$6:$L$63) -> 0.45436048 | V63: -1.779547 | W63: 1.2200709 | X63: -1.2087766 | Y63: 0.65017863 | Z63: 0.60363889
A64: Median | B64: 19467 | C64: 7914 | D64: 4832 | E64: 2786 | F64: 1735 | G64: 976 | H64: 494 | I64: 232 | J64: 126 | K64: 193 | L64: =AVERAGE(L9:L62) -> -4.6148148 | M64: Avg | V64: 0.45436048 | W64: -1.779547 | X64: 1.2200709 | Y64: -1.2087766 | Z64: 0.65017863
A65: Average | B65: 22002 | C65: 8860 | D65: 5459 | E65: 3632 | F65: 2286 | G65: 1325 | H65: 753 | I65: 415 | J65: 231 | K65: 296 | L65: =STDEV(L9:L62) -> 1.1722781 | M65: SD | W65: 0.45436048 | X65: -1.779547 | Y65: 1.2200709 | Z65: -1.2087766
X66: 0.45436048 | Y66: -1.779547 | Z66: 1.2200709
Y67: 0.45436048 | Z67: -1.779547
Z68: 0.45436048
A73: Tabl 1. Ecosystem Status Report
D75: Correlations
B77: Age-1 | C77: Age-2 | D77: Age-3 | E77: Age-4 | F77: Age-5 | G77: Age-6
A78: 1964-2017 | B78: =I88 -> 0.35422002 | C78: =J89 -> 0.34617974 | D78: =K90 -> 0.33085347 | E78: =L91 -> 0.27422696 | F78: =M92 -> 0.23060661 | G78: =N93 -> 0.21208231
A79: 1996-2017 | B79: =I150 -> 0.3831134 | C79: =J151 -> 0.39740244 | D79: =K152 -> 0.43789234 | E79: =L153 -> 0.38721574 | F79: =M154 -> 0.35643408 | G79: =N155 -> 0.41139333
A85: Linear Correlation Matrix
B86: ='2017 Ianelli'!$N$2 -> Year | C86: ='2017 Ianelli'!$O$2 -> age-1 | D86: ='2017 Ianelli'!$P$2 -> Age-2 | E86: ='2017 Ianelli'!$Q$4 -> Age-3 (yr) | F86: ='2017 Ianelli'!$R$2 -> Age-4 | G86: ='2017 Ianelli'!$S$2 -> Age-5 | H86: ='2017 Ianelli'!$T$2 -> Age-6 | I86: ='2017 Ianelli'!$U$2 -> TC index (yr-2) | J86: ='2017 Ianelli'!$V$2 -> TC index2 | K86: ='2017 Ianelli'!$W$2 -> TC index3 | L86: ='2017 Ianelli'!$X$2 -> TC index4 | M86: ='2017 Ianelli'!$Y$2 -> TCindex5 | N86: ='2017 Ianelli'!$Z$2 -> TCindex6
...

Sheet pollock Model 2017 data
A1: Table | B1: 1.3 | C1: Estimates | D1: millions | E1: of | F1: EBS | G1: pollock | H1: at | I1: age | J1: from | K1: the | L1: 2016 | M1: model. | O1: 2017 model
A2: year | B2: 1 | C2: 2 | D2: 3 | E2: 4 | F2: 5 | G2: 6 | H2: 7 | I2: 8 | J2: 9 | K2: 10+ | L2: Total | O2: Year | P2: 1 | Q2: 2 | R2: 3 | S2: 4 | T2: 5 | U2: 6 | V2: 7 | W2: 8 | X2: 9 | Y2: 10+
A3: 1964 | B3: 6670 | C3: 3534 | D3: 2242 | E3: 483 | F3: 209 | G3: 406 | H3: 183 | I3: 59 | J3: 37 | K3: 225 | L3: 14048 | O3: 1964 | P3: 6.43 | Q3: 3.46 | R3: 2.19 | S3: 0.47 | T3: 0.2 | U3: 0.39 | V3: 0.18 | W3: 0.06 | X3: 0.04 | Y3: 0.22
A4: 1965 | B4: 21535 | C4: 2706 | D4: 2223 | E4: 1588 | F4: 304 | G4: 131 | H4: 256 | I4: 116 | J4: 38 | K4: 169 | L4: 29067 | O4: 1965 | P4: 21.16 | Q4: 2.61 | R4: 2.18 | S4: 1.55 | T4: 0.29 | U4: 0.13 | V4: 0.25 | W4: 0.11 | X4: 0.04 | Y4: 0.16
A5: 1966 | B5: 15437 | C5: 8737 | D5: 1702 | E5: 1563 | F5: 994 | G5: 192 | H5: 83 | I5: 163 | J5: 75 | K5: 134 | L5: 29079 | O5: 1966 | P5: 15.16 | Q5: 8.59 | R5: 1.64 | S5: 1.53 | T5: 0.96 | U5: 0.18 | V5: 0.08 | W5: 0.16 | X5: 0.07 | Y5: 0.13
A6: 1967 | B6: 25796 | C6: 6263 | D6: 5491 | E6: 1191 | F6: 994 | G6: 634 | H6: 123 | I6: 54 | J6: 106 | K6: 136 | L6: 40789 | O6: 1967 | P6: 25.65 | Q6: 6.15 | R6: 5.4 | S6: 1.15 | T6: 0.97 | U6: 0.61 | V6: 0.12 | W6: 0.05 | X6: 0.1 | Y6: 0.13
A7: 1968 | B7: 22271 | C7: 10448 | D7: 3883 | E7: 3593 | F7: 698 | G7: 582 | H7: 373 | I7: 73 | J7: 32 | K7: 144 | L7: 42097 | O7: 1968 | P7: 22.19 | Q7: 10.39 | R7: 3.81 | S7: 3.52 | T7: 0.67 | U7: 0.56 | V7: 0.36 | W7: 0.07 | X7: 0.03 | Y7: 0.14
A8: 1969 | B8: 26141 | C8: 9015 | D8: 6455 | E8: 2536 | F8: 2103 | G8: 411 | H8: 345 | I8: 222 | J8: 43 | K8: 105 | L8: 47377 | O8: 1969 | P8: 26.18 | Q8: 8.98 | R8: 6.42 | S8: 2.49 | T8: 2.04 | U8: 0.39 | V8: 0.33 | W8: 0.21 | X8: 0.04 | Y8: 0.1
A9: 1970 | B9: 23500 | C9: 10572 | D9: 5546 | E9: 4094 | F9: 1500 | G9: 1250 | H9: 246 | I9: 206 | J9: 131 | K9: 87 | L9: 47133 | O9: 1970 | P9: 23.52 | Q9: 10.59 | R9: 5.52 | S9: 4.06 | T9: 1.46 | U9: 1.21 | V9: 0.23 | W9: 0.2 | X9: 0.12 | Y9: 0.08
A10: 1971 | B10: 14578 | C10: 9468 | D10: 6356 | E10: 3312 | F10: 2351 | G10: 840 | H10: 701 | I10: 136 | J10: 110 | K10: 114 | L10: 37967 | O10: 1971 | P10: 14.46 | Q10: 9.47 | R10: 6.36 | S10: 3.29 | T10: 2.32 | U10: 0.81 | V10: 0.67 | W10: 0.13 | X10: 0.1 | Y10: 0.1
A11: 1972 | B11: 11964 | C11: 5851 | D11: 5550 | E11: 3570 | F11: 1747 | G11: 1178 | H11: 424 | I11: 351 | J11: 64 | K11: 100 | L11: 30800 | O11: 1972 | P11: 11.83 | Q11: 5.8 | R11: 5.55 | S11: 3.57 | T11: 1.73 | U11: 1.15 | V11: 0.4 | W11: 0.33 | X11: 0.06 | Y11: 0.09
A12: 1973 | B12: 26909 | C12: 4808 | D12: 3324 | E12: 2898 | F12: 1744 | G12: 839 | H12: 567 | I12: 203 | J12: 158 | K12: 69 | L12: 41519 | O12: 1973 | P12: 26.95 | Q12: 4.75 | R12: 3.3 | S12: 2.89 | T12: 1.73 | U12: 0.82 | V12: 0.55 | W12: 0.19 | X12: 0.15 | Y12: 0.06
A13: 1974 | B13: 19909 | C13: 10829 | D13: 2649 | E13: 1612 | F13: 1306 | G13: 773 | H13: 372 | I13: 251 | J13: 85 | K13: 91 | L13: 37877 | O13: 1974 | P13: 19.77 | Q13: 10.85 | R13: 2.62 | S13: 1.59 | T13: 1.29 | U13: 0.76 | V13: 0.36 | W13: 0.24 | X13: 0.08 | Y13: 0.08
A14: 1975 | B14: 17094 | C14: 8023 | D14: 5763 | E14: 1144 | F14: 691 | G14: 558 | H14: 331 | I14: 159 | J14: 102 | K14: 68 | L14: 33934 | O14: 1975 | P14: 16.77 | Q14: 7.97 | R14: 5.76 | S14: 1.12 | T14: 0.67 | U14: 0.54 | V14: 0.32 | W14: 0.15 | X14: 0.1 | Y14: 0.06
... A55: 2016 | B55: 18951 | C55: 7391 | D55: 8251 | E55: 11696 | F55: 1415 | G55: 1090 | H55: 1003 | I55: 1552 | J55: 244 | K55: 217 | L55: 51810 | O55: 2016 | P55: 18.24 | Q55: 7.02 | R55: 10.32 | S55: 11.02 | T55: 1.37 | U55: 1 | V55: 0.9 | W55: 1.31 | X55: 0.2 | Y55: 0.16
A56: Median | B56: 19430 | C56: 7707 | D56: 4440 | E56: 2896 | F56: 1773 | G56: 1070 | H56: 585 | I56: 273 | J56: 137 | K56: 187 | L56: 45162 | O56: 2017 | P56: 18.47 | Q56: 7.42 | R56: 4.47 | S56: 7.56 | T56: 6.98 | U56: 0.88 | V56: 0.59 | W56: 0.52 | X56: 0.77 | Y56: 0.22
A57: Average | B57: 22993 | C57: 9255 | D57: 5727 | E57: 3807 | F57: 2316 | G57: 1401 | H57: 794 | I57: 435 | J57: 226 | K57: 289 | L57: 47242
